=== НАЧАЛО ОБУЧЕНИЯ 2025-08-26 17:22:13 ===

[2025-08-26 17:22:13] === РЕЖИМ МАСШТАБИРОВАНИЯ: FULL ===
[2025-08-26 17:22:13] Пользователей: все
[2025-08-26 17:22:13] Данных: 100.0%
[2025-08-26 17:22:13] === ЗАГРУЗКА ДАННЫХ ===
[2025-08-26 17:22:13] Загружаем данные...
[2025-08-26 17:22:13] orders: 1,000,000 строк (использовано 28 из 28 партиций), ~2.0 MB
[2025-08-26 17:22:14] tracker: 1,000,000 строк (использовано 298 из 298 партиций), ~32.3 MB
[2025-08-26 17:22:15] items: 1,000,000 строк (использовано 200 из 200 партиций), ~7.4 MB
[2025-08-26 17:22:15] categories: 7,012 строк (использовано 1 из 1 партиций), ~1.7 MB
[2025-08-26 17:22:15] test_users: 470,347 строк (использовано 1 из 1 партиций), ~1.8 MB
[2025-08-26 17:22:15] Данные загружены
[2025-08-26 17:22:15] Фильтрация данных...
[2025-08-26 17:22:15] Фильтрация завершена
[2025-08-26 17:22:15] Загрузка данных завершена за 0:00:01.819733
[2025-08-26 17:22:15] === SPLIT ДАННЫХ ===
[2025-08-26 17:22:15] Split данных завершен за 0:00:00.034223
[2025-08-26 17:22:15] Train orders: 37867, Test orders: 9461
[2025-08-26 17:22:15] Считаем глобальную популярность на основе тренировочных данных...
[2025-08-26 17:22:15] Глобальная популярность рассчитана на 37861 тренировочных заказах
[2025-08-26 17:22:15] Популярность рассчитана: 32733 товаров
[2025-08-26 17:22:15] === ПОДГОТОВКА ДАННЫХ ДЛЯ LightGBM ===
[2025-08-26 17:22:15] Подготовка данных для LightGBM (streaming) с GPU...
[2025-08-26 17:22:15] !!! ОШИБКА ВЫПОЛНЕНИЯ !!!
[2025-08-26 17:22:15] Ошибка: No objects to concatenate
[2025-08-26 17:22:15] Время до ошибки: 0:00:01.864032
[2025-08-26 17:22:15] Трассировка ошибки:
[2025-08-26 17:22:15] Traceback (most recent call last):
  File "/home/root6/python/e_cup/rec_system/src/prepare/with_ml.py", line 2319, in <module>
    train_data, val_data = recommender.prepare_training_data(
                           ^^^^^^^^^^^^^^^^^^^^^^^^^^^^^^^^^^
  File "/home/root6/python/e_cup/rec_system/src/prepare/with_ml.py", line 1201, in prepare_training_data
    interactions_df = pd.concat(interactions_chunks, ignore_index=True)
                      ^^^^^^^^^^^^^^^^^^^^^^^^^^^^^^^^^^^^^^^^^^^^^^^^^
  File "/home/root6/python/e_cup/venv/lib/python3.12/site-packages/pandas/core/reshape/concat.py", line 382, in concat
    op = _Concatenator(
         ^^^^^^^^^^^^^^
  File "/home/root6/python/e_cup/venv/lib/python3.12/site-packages/pandas/core/reshape/concat.py", line 445, in __init__
    objs, keys = self._clean_keys_and_objs(objs, keys)
                 ^^^^^^^^^^^^^^^^^^^^^^^^^^^^^^^^^^^^^
  File "/home/root6/python/e_cup/venv/lib/python3.12/site-packages/pandas/core/reshape/concat.py", line 507, in _clean_keys_and_objs
    raise ValueError("No objects to concatenate")
ValueError: No objects to concatenate


=== ОБЩЕЕ ВРЕМЯ ВЫПОЛНЕНИЯ: 0:00:01.864564 ===
